Workbook

Sheet Pivot table
A1: What is the % of delayed batches from production duration? | F1: What is the number of batches, delayed, and on-time in each shift? | L1: Which are the top 5 batches with the most downtime? | Q1: What are the most frequent downtime factors contributing to production delays? | X1: Did every delayed batch have downtime? | AC1: Is Product_id associated with a higher delay rate? | AI1: Get the products that are marked as both on time and delayed? | AQ1: Does the delay rate differ between operators? | AV1: Get the Operator that are marked as both on time and delayed? | BC1: Does a specific shift have more delays? | BH1: Does downtime increase in a specific shift? | BN1: Is the delay % increasing over days? | BS1: Does downtime change over time? | BX1: What proportion of downtime is due to operator error vs. equipment factors?
A3: Row Labels | B3: Count of Batch | X3: Row Labels | Y3: Sum of Duration_MIn | Z3: Count of Batch | AC3: Row Labels | AD3: Sum of Duration_MIn | AQ3: Row Labels | AR3: Sum of Duration_MIn | AV3: Count of Batch | AW3: Column Labels
A4: Delayed | B4: 0.92105263 | F4: Row Labels | G4: Count of Batch | L4: Row Labels | M4: Total Downtime | Q4: Row Labels | R4: Count of Batch | X4: Delayed | Y4: 1388 | Z4: 35 | AC4: CO-600 | AD4: 0.35590778 | AI4: Count of Batch | AJ4: Column Labels | AQ4: Charlie | AR4: 0.27665706 | AV4: Row Labels | AW4: Delayed | AX4: On Time | AY4: Grand Total | BC4: Production_status | BD4: Delayed | BH4: Row Labels | BI4: Total Downtime | BN4: Count of Batch | BO4: Column Labels | BS4: Row Labels | BT4: Total Downtime | BX4: Row Labels | BY4: Sum of Duration_MIn
A5: On Time | B5: 0.078947368 | F5: Afternoon | G5: 16 | L5: 422147 | M5: 107 | Q5: Machine adjustment | R5: 12 | X5: Grand Total | Y5: 1388 | Z5: 35 | AC5: CO-2L | AD5: 0.19956772 | AI5: Row Labels | AJ5: Delayed | AK5: On Time | AL5: Grand Total | AQ5: Dee | AR5: 0.26657061 | AV5: Charlie | AW5: 10 | AX5: 1 | AY5: 11 | BH5: Afternoon | BI5: 584 | BN5: Row Labels | BO5: Delayed | BS5: أغسطس | BX5: Operator | BY5: 0.55907781
A6: Grand Total | B6: 1 | F6: Delayed | G6: 14 | L6: 422111 | M6: 75 | Q6: Machine failure | R6: 11 | AC6: RB-600 | AD6: 0.18587896 | AI6: CO-600 | AJ6: 14 | AK6: 1 | AL6: 15 | AQ6: Mac | AR6: 0.23919308 | AV6: Dee | AW6: 10 | AX6: 1 | AY6: 11 | BC6: Row Labels | BD6: Count of Batch | BH6: Morning | BI6: 534 | BN6: أغسطس | BS6: 45533 | BT6: 244 | BX6: Non Operator | BY6: 0.44092219
F7: On Time | G7: 2 | L7: 422123 | M7: 73 | Q7: Inventory shortage | R7: 9 | AC7: LE-600 | AD7: 0.12175793 | AI7: DC-600 | AJ7: 3 | AK7: 1 | AL7: 4 | AQ7: Dennis | AR7: 0.21757925 | AV7: Mac | AW7: 7 | AX7: 1 | AY7: 8 | BC7: Afternoon | BD7: 0.4 | BH7: Night | BI7: 270 | BN7: 45533 | BO7: 0.17142857 | BS7: 45534 | BT7: 444 | BX7: Grand Total | BY7: 1
F8: Morning | G8: 15 | L8: 422140 | M8: 63 | Q8: Other | R8: 6 | AC8: DC-600 | AD8: 0.082853026 | AI8: LE-600 | AJ8: 5 | AK8: 1 | AL8: 6 | AQ8: Grand Total | AR8: 1 | AV8: Grand Total | AW8: 27 | AX8: 3 | AY8: 30 | BC8: Morning | BD8: 0.4 | BH8: Grand Total | BI8: 1388 | BN8: 45534 | BO8: 0.34285714 | BS8: 45535 | BT8: 165
F9: Delayed | G9: 14 | L9: 422146 | M9: 62 | Q9: Batch coding error | R9: 6 | AC9: OR-600 | AD9: 0.054034582 | AI9: Grand Total | AJ9: 22 | AK9: 3 | AL9: 25 | BC9: Night | BD9: 0.2 | BN9: 45535 | BO9: 0.14285714 | BS9: سبتمبر
F10: On Time | G10: 1 | L10: Grand Total | M10: 380 | Q10: Batch change | R10: 5 | AC10: Grand Total | AD10: 1 | BC10: Grand Total | BD10: 1 | BN10: سبتمبر | BS10: 45537 | BT10: 503
A11: Is delay exception or is it the normal? | F11: Night | G11: 7 | Q11: Product spill | R11: 3 | BN11: 45537 | BO11: 0.31428571 | BS11: 45538 | BT11: 32
F12: Delayed | G12: 7 | Q12: Calibration error | R12: 3 | BN12: 45538 | BO12: 0.028571429 | BS12: Grand Total | BT12: 1388
A13: Delayed | B13: 0.92105263 | F13: Grand Total | G13: 38 | Q13: Label switch | R13: 3 | BN13: Grand Total | BO13: 1
Q14: Labeling error | R14: 2
Q15: Conveyor belt jam | R15: 1
Q16: Grand Total | R16: 61
A19: What is the total downtime on the line?
BI20: Row Labels | BJ20: Total Downtime
BI21: Afternoon | BJ21: 584
A22: Total Downtime | BI22: Morning | BJ22: 534
A23: 1388 | BI23: Night | BJ23: 270
BI24: Grand Total | BJ24: 1388

Sheet Productivity Analysis 
A1: 1- Is the number of batches increasing or decreasing over time? | G1: 2- How many batches does each shift complete on average? | M1: 3- What is the percentage of each product to total batches? | S1: 4- Compare total actual operating hours vs ideal required hours? | X1: 5- How many hours per day does the line operate out of 24 hours? | AC1: 6- Which Top 5 batch took the longest time ? | AG1: 7- How many times was the product changed per day? | AK1: 8- What is the total number of batches for each product? | AS1: 9- Top 10 between Actual Production Duration and Ideal Time for each batch? | AY1: 10- Which shift (Morning, Afternoon, Night) has the highest delay rate versus ideal time? | BE1: 11- Do large-size products (2L) experience higher delays than small-size bottles (600ml)? | BL1: KPI--Productivity Score (%)
A3: Row Labels | B3: Count of Batch | G3: Row Labels | H3: Count of Batch | M3: Row Labels | N3: Count of Batch | S3: Row Labels | T3: Total_Actual_Minutes | U3: Total_Ideal_Minutes | X3: Utilization_Rate | AC3: Row Labels | AD3: Sum of Production Duration | AG3: Row Labels | AH3: Sum of Changeover Count | AK3: Row Labels | AL3: Count of Batch | AS3: Row Labels | AT3: Total_Actual_Minutes | AU3: Total_Ideal_Minutes | AY3: Row Labels | AZ3: Total_Actual_Minutes | BA3: Total_Ideal_Minutes | BE3: Row Labels | BF3: Total Downtime | BL3: Productivity Score
A4: 45533 | B4: 7 | G4: Afternoon | H4: 16 | M4: CO-600 | N4: 0.39473684 | S4: CO-2L | T4: 767 | U4: 490 | X4: 0.6402281 | AC4: 422147 | AG4: 45533 | AH4: 2 | AK4: CO-600 | AL4: 15 | AS4: 422111 | AT4: 135 | AU4: 60 | AY4: Afternoon | AZ4: 1658 | BA4: 1074 | BE4: CO-2L | BF4: 277 | BL4: 0.6402281
A5: 45534 | B5: 12 | G5: Morning | H5: 15 | M5: RB-600 | N5: 0.18421053 | S5: CO-600 | T5: 1394 | U5: 900 | AC5: CO-2L | AD5: 205 | AG5: 45534 | AH5: 1 | AK5: RB-600 | AL5: 7 | AS5: 422118 | AT5: 120 | AU5: 60 | AY5: Morning | AZ5: 1472 | BA5: 938 | BE5: CO-600 | BF5: 494
A6: 45535 | B6: 7 | G6: Night | H6: 7 | M6: LE-600 | N6: 0.15789474 | S6: DC-600 | T6: 355 | U6: 240 | AC6: 422111 | AG6: 45535 | AH6: 1 | AK6: LE-600 | AL6: 6 | AS6: 422123 | AT6: 133 | AU6: 60 | AY6: Night | AZ6: 728 | BA6: 458 | BE6: DC-600 | BF6: 115
A7: 45537 | B7: 11 | G7: Grand Total | H7: 38 | M7: CO-2L | N7: 0.13157895 | S7: LE-600 | T7: 529 | U7: 360 | AC7: OR-600 | AD7: 135 | AG7: 45537 | AH7: 2 | AK7: CO-2L | AL7: 5 | AS7: 422140 | AT7: 123 | AU7: 60 | AY7: Grand Total | AZ7: 3858 | BA7: 2470 | BE7: LE-600 | BF7: 169 | BL7: Average Delay per Batch
A8: 45538 | B8: 1 | M8: DC-600 | N8: 0.10526316 | S8: OR-600 | T8: 135 | U8: 60 | AC8: 422123 | AG8: 45538 | AH8: 0 | AK8: DC-600 | AL8: 4 | AS8: 422143 | AT8: 118 | AU8: 60 | BE8: OR-600 | BF8: 75
A9: Grand Total | B9: 38 | M9: OR-600 | N9: 0.026315789 | S9: RB-600 | T9: 678 | U9: 420 | AC9: CO-600 | AD9: 133 | AG9: Grand Total | AH9: 6 | AK9: OR-600 | AL9: 1 | AS9: 422144 | AT9: 152 | AU9: 98 | BE9: RB-600 | BF9: 258 | BL9: Row Labels | BM9: Average of Production Duration
M10: Grand Total | N10: 1 | S10: Grand Total | T10: 3858 | U10: 2470 | AC10: 422144 | AK10: Grand Total | AL10: 38 | AS10: 422145 | AT10: 120 | AU10: 98 | BE10: Grand Total | BF10: 1388 | BL10: Delayed | BM10: 105.08571
AC11: CO-2L | AD11: 152 | AS11: 422146 | AT11: 160 | AU11: 98 | BL11: Grand Total | BM11: 105.08571
AC12: 422146 | AS12: 422147 | AT12: 205 | AU12: 98
AC13: CO-2L | AD13: 160 | AS13: 422148 | AT13: 130 | AU13: 98
AC14: Grand Total | AD14: 785 | AK14: _What is the average actual production duration for each product? | AS14: Grand Total | AT14: 1396 | AU14: 790
BL15: On-Time Delivery Rate (OTDR)
AK16: Row Labels | AL16: Average of Production Duration
AK17: CO-2L | AL17: 153.4 | BL17: On Time | BM17: 0.078947368
AC18: _ Which Top 5 was the fastest batch completed? | AK18: CO-600 | AL18: 92.933333
AK19: DC-600 | AL19: 88.75
AC20: Row Labels | AD20: Sum of Production Duration | AK20: LE-600 | AL20: 88.166667
AC21: 422116 | AK21: OR-600 | AL21: 135 | BL21: Each product’s share of total production
AC22: LE-600 | AD22: 60 | AK22: RB-600 | AL22: 96.857143
AC23: 422129 | AK23: Grand Total | AL23: 101.52632 | BL23: Row Labels | BM23: Product Share
AC24: CO-600 | AD24: 75 | BL24: CO-2L | BM24: 0.33557047
AC25: 422132 | BL25: CO-600 | BM25: 0.30201342
AC26: CO-600 | AD26: 60 | AK26: _How many times was the status marked as ON TIME versus DELAY? | BL26: DC-600 | BM26: 0.080536913
AC27: 422136 | BL27: LE-600 | BM27: 0.12080537
AC28: DC-600 | AD28: 60 | AK28: Row Labels | AL28: Count of Batch | BL28: OR-600 | BM28: 0.020134228
AC29: 422141 | AK29: Delayed | AL29: 0.92105263 | BL29: RB-600 | BM29: 0.1409396
AC30: RB-600 | AD30: 67 | AK30: On Time | AL30: 0.078947368 | BL30: Grand Total | BM30: 1
AC31: Grand Total | AD31: 322 | AK31: Grand Total | AL31: 1
BL32: What is the average delay time for batches marked DELAY only?
AK34: _Which day recorded the highest production for batch? | BL34: Production_status | BM34: Delayed
AK36: Row Labels | AL36: Count of Batch | BL36: Average of Production Duration
AK37: 45534 | AL37: 12 | BL37: 105.08571
AK38: 45537 | AL38: 11
AK39: 45533 | AL39: 7
AK40: 45535 | AL40: 7
AK41: 45538 | AL41: 1 | BL41: Total Batchs
AK42: Grand Total | AL42: 38
BL43: Count of Batch
...

Sheet Downtime Analysis
A1: 1- What is the most frequent downtime factor? | H1: 2- Which 20% of causes are responsible for 80% of lost time? | O1: 3- Are certain operators associated with repeated Operator Errors? | U1: 4- What is the Total Downtime (min) for each shift ? | Z1: 5- Is any shift associated with higher Machine Failure incidents? | AF1: KPI- Total Downtime | AI1: 6- Do all DELAY batches have recorded downtime causes?
A3: Row Labels | B3: Sum of Duration_MIn | H3: Row Labels | I3: Sum of Duration_MIn | J3: Sum of Duration_MIn2 | O3: Count of Downtime_id | P3: Column Labels | U3: Row Labels | V3: Total Downtime | Z3: Count of Downtime_id | AA3: Column Labels | AF3: Total Downtime | AI3: Row Labels | AJ3: Sum of Duration_MIn
A4: Machine adjustment | B4: 332 | H4: Batch change | I4: 160 | J4: 0.11527378 | O4: Row Labels | P4: Non Operator | Q4: Operator | R4: Grand Total | U4: Afternoon | V4: 584 | Z4: Row Labels | AA4: Machine failure | AF4: 1388 | AI4: Delayed | AJ4: 1388
A5: Machine failure | B5: 254 | H5: Batch coding error | I5: 145 | J5: 0.21974063 | O5: Charlie | P5: 8 | Q5: 9 | R5: 17 | U5: Morning | V5: 534 | Z5: Morning | AA5: 7 | AI5: Grand Total | AJ5: 1388
A6: Inventory shortage | B6: 225 | H6: Calibration error | I6: 49 | J6: 0.25504323 | O6: Dee | P6: 9 | Q6: 10 | R6: 19 | U6: Night | V6: 270 | Z6: Afternoon | AA6: 3
A7: Batch change | B7: 160 | H7: Conveyor belt jam | I7: 17 | J7: 0.26729107 | O7: Dennis | P7: 6 | Q7: 6 | R7: 12 | U7: Grand Total | V7: 1388 | Z7: Night | AA7: 1 | AF7: Avg. Downtime_Min
A8: Batch coding error | B8: 145 | H8: Inventory shortage | I8: 225 | J8: 0.42939481 | O8: Mac | P8: 6 | Q8: 7 | R8: 13 | Z8: Grand Total | AA8: 11
A9: Grand Total | B9: 1116 | H9: Label switch | I9: 33 | J9: 0.45317003 | O9: Grand Total | P9: 29 | Q9: 32 | R9: 61 | AF9: Average of Duration_MIn
H10: Labeling error | I10: 42 | J10: 0.48342939 | AF10: 22.754098
H11: Machine adjustment | I11: 332 | J11: 0.72262248
H12: Machine failure | I12: 254 | J12: 0.9056196
H13: Other | I13: 74 | J13: 0.95893372 | AF13: Downtime_Percentage
H14: Product spill | I14: 57 | J14: 1
H15: Grand Total | I15: 1388 | AF15: Downtime_Percentage
AF16: 0.56194332
A19: _Which factor consumes the highest downtime duration? | AF19: Availability Rate
A21: Row Labels | B21: Sum of Duration_MIn | AF21: Uptime Ratio
A22: Machine adjustment | B22: 332 | AF22: 0.43805668
A23: Machine failure | B23: 254
A24: Inventory shortage | B24: 225
A25: Batch change | B25: 160 | AF25: Production Loss (Batches)
A26: Batch coding error | B26: 145
A27: Other | B27: 74 | AF27: Lost_Batches_Count
A28: Product spill | B28: 57 | AF28: 20.924623
A29: Calibration error | B29: 49
A30: Labeling error | B30: 42
A31: Label switch | B31: 33 | AF31: Mean Time Between Failures (Min)
A32: Conveyor belt jam | B32: 17
A33: Grand Total | B33: 1388 | AF33: MTBF
AF34: 63.245902
AF37: Human Error Impact (%)
A38: _What is the total downtime for each shift?
AF39: Human Error Downtime %
A40: Row Labels | B40: Total Downtime | AF40: 0.55907781
A41: Afternoon | B41: 584
A42: Morning | B42: 534
A43: Night | B43: 270
A44: Grand Total | B44: 1388
A48: _What is the total downtime for each day?
A50: Row Labels | B50: Total Downtime
...

Sheet Operator Analysis
A1: 1. Which operator recorded the highest number of batches? | G1: 2. Which operator has the lowest average production time for the same product? | O1: 3. What is each operator’s ON TIME percentage? | R1: 4.Which operator performs closest to Min_Batch_Time? | W1: 5. Which operator is associated with the highest number of operator errors? | AC1: 6.What type of human error is most common for each operator? | AH1: 7.How many downtime minutes did each operator contribute? | AM1: 8- Which operator restores operation fastest after a failure? | AT1: 9- Does operator efficiency drop when moving from 600ml products to 2L products? | BA1: 10. Is operator performance consistent across shifts? | BG1: KPI- Operator Efficiency Index
A3: Row Labels | B3: Count of Batch | G3: Row Labels | H3: Average of Production Duration | O3: Count of Batch | P3: Column Labels | R3: Row Labels | S3: Time_Variance_Min | W3: Count of Downtime_id | X3: Column Labels | AC3: Operator Error | AD3: Operator | AH3: Row Labels | AI3: Sum of Duration_MIn | AM3: Row Labels | AN3: Avg_Repair_Time | AT3: Total_Actual_Minutes | AU3: Column Labels | BA3: Row Labels | BB3: Utilization_Rate | BG3: Row Labels | BH3: Operator Efficiency
A4: Charlie | B4: 11 | G4: Charlie | O4: Row Labels | P4: On Time | R4: Charlie | S4: 384 | W4: Row Labels | X4: Operator | AH4: Charlie | AI4: 384 | AM4: Charlie | AN4: 22.588235 | AT4: Row Labels | AU4: 2 L | AV4: 600 ml | BA4: Afternoon | BG4: Charlie | BH4: 66.839378
A5: Dee | B5: 11 | G5: LE-600 | H5: 73 | O5: Charlie | P5: 0.33333333 | R5: Dee | S5: 370 | W5: Dee | X5: 10 | AC5: Row Labels | AD5: Count of Downtime_id | AH5: Dee | AI5: 370 | AM5: Dee | AN5: 19.473684 | AT5: Charlie | AU5: 485 | AV5: 673 | BA5: Charlie | BB5: 0.65927978 | BG5: Dee | BH5: 64.07767
A6: Mac | B6: 8 | G6: CO-600 | H6: 90.8 | O6: Dee | P6: 0.33333333 | R6: Mac | S6: 332 | W6: Charlie | X6: 9 | AC6: Dee | AH6: Mac | AI6: 332 | AM6: Dennis | AN6: 25.166667 | AT6: Dee | AV6: 1030 | BA6: Dennis | BB6: 0.6 | BG6: Dennis | BH6: 63.170732
A7: Dennis | B7: 8 | G7: CO-2L | H7: 161.66667 | O7: Mac | P7: 0.33333333 | R7: Dennis | S7: 302 | W7: Mac | X7: 7 | AC7: Machine adjustment | AD7: 3 | AH7: Dennis | AI7: 302 | AM7: Mac | AN7: 25.538462 | AT7: Dennis | AU7: 152 | AV7: 668 | BA7: Mac | BB7: 0.63157895 | BG7: Mac | BH7: 60.941176
A8: Grand Total | B8: 38 | G8: Dee | O8: Grand Total | P8: 1 | R8: Grand Total | S8: 1388 | W8: Dennis | X8: 6 | AC8: Charlie | AH8: Grand Total | AI8: 1388 | AM8: Grand Total | AN8: 22.754098 | AT8: Mac | AU8: 130 | AV8: 720 | BA8: Morning | BG8: Grand Total | BH8: 64.02281
G9: DC-600 | H9: 80 | W9: Grand Total | X9: 32 | AC9: Machine adjustment | AD9: 4 | AT9: Grand Total | AU9: 767 | AV9: 3091 | BA9: Dee | BB9: 0.71005917
G10: CO-600 | H10: 91.166667 | AC10: Dennis | BA10: Dennis | BB10: 0.63611111 | BG10: Average production time without Operator Errors
G11: RB-600 | H11: 100.75 | AC11: Machine adjustment | AD11: 4 | BA11: Mac | BB11: 0.48979592
G12: Dennis | AC12: Mac | BA12: Night | BG12: Row Labels | BH12: Error-Free Run Time
G13: RB-600 | H13: 91.666667 | AC13: Batch change | AD13: 3 | BA13: Charlie | BB13: 0.8 | BG13: Charlie | BH13: 85
G14: CO-600 | H14: 98.25 | AC14: Grand Total | AD14: 14 | BA14: Dee | BB14: 0.57361377 | BG14: Dee | BH14: 76.25
G15: CO-2L | H15: 152 | BA15: Mac | BB15: 0.75384615 | BG15: Dennis | BH15: 90
G16: Mac | BA16: Grand Total | BB16: 0.6402281 | BG16: Mac | BH16: 82.5
G17: DC-600 | H17: 91.666667 | BG17: Grand Total | BH17: 83.461538
G18: LE-600 | H18: 103.33333
G19: CO-2L | H19: 130 | BG19: Estimated waste or lost time caused by each operator.
G20: OR-600 | H20: 135 | BG20: Row Labels | BH20: Waste Contribution
G21: Grand Total | H21: 101.52632 | BG21: Charlie | BH21: 228
BG22: Dee | BH22: 192
BG23: Dennis | BH23: 164
BG24: Mac | BH24: 192
BG25: Grand Total | BH25: 776
BG28: Row Labels | BH28: Error-Free Run Time
BG29: Charlie | BH29: 85
BG30: Dee | BH30: 76.25
BG31: Dennis | BH31: 90
BG32: Mac | BH32: 82.5
BG33: Grand Total | BH33: 83.461538

Sheet Shift Productivity
A1: 1- Which shift produces the highest batch volume? | H1: 2- Does a certain shift have more downtime? | N1: 3- Which shift performs best against target time | T1: 4- Is any shift associated with more Operator Errors? | Y1: KPI-On-Time Delivery Rate per Shift
A3: Row Labels | B3: Count of Batch | H3: Row Labels | I3: Total Downtime | N3: Row Labels | O3: Utilization_Rate | T3: Operator Error | U3: Operator | Y3: Count of Batch | Z3: Column Labels
A4: Afternoon | B4: 16 | H4: Afternoon | I4: 584 | N4: Afternoon | O4: 0.6477684 | Y4: Row Labels | Z4: Delayed | AA4: On Time
A5: Morning | B5: 15 | H5: Morning | I5: 534 | N5: Morning | O5: 0.63722826 | T5: Row Labels | U5: Count of Downtime_id | Y5: Afternoon | Z5: 0.875 | AA5: 0.125
A6: Night | B6: 7 | H6: Night | I6: 270 | N6: Night | O6: 0.62912088 | T6: Afternoon | U6: 15 | Y6: Morning | Z6: 0.93333333 | AA6: 0.066666667
A7: Grand Total | B7: 38 | H7: Grand Total | I7: 1388 | N7: Grand Total | O7: 0.6402281 | T7: Morning | U7: 9 | Y7: Night | Z7: 1 | AA7: 0
T8: Night | U8: 8 | Y8: Grand Total | Z8: 0.92105263 | AA8: 0.078947368
T9: Grand Total | U9: 32
H10: _Are these failures machine-related or material shortages | Y10: Human Factor Impact
Y11: Sum of Duration_MIn | Z11: Column Labels
H12: Row Labels | I12: Count of Downtime_id | Y12: Row Labels | Z12: Non Operator | AA12: Operator
H13: Afternoon | Y13: Charlie | Z13: 0.40625 | AA13: 0.59375
H14: Batch change | I14: 3 | Y14: Dee | Z14: 0.48108108 | AA14: 0.51891892
H15: Batch coding error | I15: 2 | Y15: Dennis | Z15: 0.45695364 | AA15: 0.54304636
H16: Calibration error | I16: 1 | Y16: Mac | Z16: 0.42168675 | AA16: 0.57831325
H17: Inventory shortage | I17: 3 | Y17: Grand Total | Z17: 0.44092219 | AA17: 0.55907781
H18: Label switch | I18: 1
H19: Labeling error | I19: 1 | Y19: Downtime Severity
H20: Machine adjustment | I20: 6 | Y20: Row Labels | Z20: Count of Downtime_id | AA20: Average of Duration_MIn
H21: Machine failure | I21: 3 | Y21: Batch change | Z21: 5 | AA21: 32
H22: Other | I22: 3 | Y22: Machine adjustment | Z22: 12 | AA22: 27.666667
H23: Product spill | I23: 2 | Y23: Inventory shortage | Z23: 9 | AA23: 25
H24: Morning | Y24: Batch coding error | Z24: 6 | AA24: 24.166667
H25: Batch change | I25: 2 | Y25: Machine failure | Z25: 11 | AA25: 23.090909
H26: Batch coding error | I26: 2 | Y26: Labeling error | Z26: 2 | AA26: 21
H27: Calibration error | I27: 1 | Y27: Product spill | Z27: 3 | AA27: 19
H28: Conveyor belt jam | I28: 1 | Y28: Conveyor belt jam | Z28: 1 | AA28: 17
H29: Inventory shortage | I29: 4 | Y29: Calibration error | Z29: 3 | AA29: 16.333333
H30: Machine adjustment | I30: 3 | Y30: Other | Z30: 6 | AA30: 12.333333
H31: Machine failure | I31: 7 | Y31: Label switch | Z31: 3 | AA31: 11
H32: Other | I32: 1 | Y32: Grand Total | Z32: 61 | AA32: 22.754098
H33: Product spill | I33: 1
H34: Night | Y34: Operator Error Occurrence
H35: Batch coding error | I35: 2
H36: Calibration error | I36: 1 | Y36: Count of Downtime_id | Z36: Column Labels
H37: Inventory shortage | I37: 2 | Y37: Row Labels | Z37: Operator
H38: Label switch | I38: 2 | Y38: Charlie
H39: Labeling error | I39: 1 | Y39: Machine adjustment | Z39: 4
H40: Machine adjustment | I40: 3 | Y40: Dee
H41: Machine failure | I41: 1 | Y41: Machine adjustment | Z41: 3
...

Sheet Product Analysis
A1: 1.Do 2L products consistently have higher delays than 600ml products? | I1: 2.Does a specific flavor cause more machine issues or Product Spill incidents? | O1: 3.How many minutes are lost during product changeovers | S1: 4.Is any product more associated with Labeling Errors or Label Switch failures? | Y1: 5.which product is the easiest and which is the most difficult for the line? | AE1: KPI-Average downtime minutes for each product
A3: Count of Batch | B3: Column Labels | I3: Row Labels | J3: Count of Batch | O3: Row Labels | P3: Sum of Duration_MIn | S3: Count of Downtime_id | T3: Column Labels | Y3: Count of Batch | Z3: Column Labels | AE3: Row Labels | AF3: Average of Duration_MIn
A4: Row Labels | B4: Delayed | I4: Machine adjustment | O4: Batch change | P4: 160 | S4: Row Labels | T4: Label switch | U4: Labeling error | Y4: Row Labels | Z4: Delayed | AE4: CO-2L | AF4: 25.181818
A5: 2 L | B5: 5 | I5: Cola | J5: 6 | O5: Batch coding error | P5: 145 | S5: CO-2L | U5: 1 | Y5: CO-600 | Z5: 14 | AE5: CO-600 | AF5: 20.583333
A6: 600 ml | B6: 30 | I6: Lemon lime | J6: 2 | O6: Grand Total | P6: 305 | S6: CO-600 | T6: 2 | Y6: RB-600 | Z6: 7 | AE6: DC-600 | AF6: 23
A7: Grand Total | B7: 35 | I7: Root Berry | J7: 4 | S7: RB-600 | T7: 1 | U7: 1 | Y7: LE-600 | Z7: 5 | AE7: LE-600 | AF7: 21.125
I8: Machine failure | S8: Grand Total | T8: 3 | U8: 2 | Y8: CO-2L | Z8: 5 | AE8: OR-600 | AF8: 37.5
I9: Cola | J9: 7 | Y9: DC-600 | Z9: 3 | AE9: RB-600 | AF9: 23.454545
I10: Diet Cola | J10: 2 | Y10: OR-600 | Z10: 1 | AE10: Grand Total | AF10: 22.754098
I11: Orange | J11: 1 | Y11: Grand Total | Z11: 35
I12: Root Berry | J12: 1 | AE12: Total Products
I13: Product spill | AE13: Count of Product_id
I14: Cola | J14: 3 | AE14: 6
I15: Grand Total | J15: 26

Sheet Line_productivity
A1: Batch | B1: Date | C1: Product_id | D1: Operator | E1: Start Time | F1: End Time | G1: Production Duration | H1: Production Duration2 | I1: Shift | J1: Production_status | K1: Changeover Count | L1: Total_Liters
A2: 422111 | B2: 45533 | C2: OR-600 | D2: Mac | E2: 0.49305556 | F2: 0.58680556 | G2: =MOD(Line_productivity[[#This Row],[End Time]] - Line_productivity[[#This Row],[Start Time]], 1) * 1440 -> 135 | H2: 0.09375 | I2: Morning | J2: Delayed | K2: =IF(Line_productivity[[#This Row],[Product_id]]<>C1, 1, 0) -> 1 | L2: =IF(VLOOKUP(Line_productivity[[#This Row],[Product_id]], Products!$A$2:$C$7, 3, 0)="2 L", 2, 0.6) -> 0.6
A3: 422112 | B3: 45533 | C3: LE-600 | D3: Mac | E3: 0.58680556 | F3: 0.65625 | G3: =MOD(Line_productivity[[#This Row],[End Time]] - Line_productivity[[#This Row],[Start Time]], 1) * 1440 -> 100 | H3: 0.069444444 | I3: Afternoon | J3: Delayed | K3: =IF(Line_productivity[[#This Row],[Product_id]]<>C2, 1, 0) -> 1 | L3: =IF(VLOOKUP(Line_productivity[[#This Row],[Product_id]], Products!$A$2:$C$7, 3, 0)="2 L", 2, 0.6) -> 0.6
A4: 422113 | B4: 45533 | C4: LE-600 | D4: Mac | E4: 0.65625 | F4: 0.73263889 | G4: =MOD(Line_productivity[[#This Row],[End Time]] - Line_productivity[[#This Row],[Start Time]], 1) * 1440 -> 110 | H4: 0.076388889 | I4: Afternoon | J4: Delayed | K4: =IF(Line_productivity[[#This Row],[Product_id]]<>C3, 1, 0) -> 0 | L4: =IF(VLOOKUP(Line_productivity[[#This Row],[Product_id]], Products!$A$2:$C$7, 3, 0)="2 L", 2, 0.6) -> 0.6
A5: 422114 | B5: 45533 | C5: LE-600 | D5: Mac | E5: 0.73263889 | F5: 0.80208333 | G5: =MOD(Line_productivity[[#This Row],[End Time]] - Line_productivity[[#This Row],[Start Time]], 1) * 1440 -> 100 | H5: 0.069444444 | I5: Afternoon | J5: Delayed | K5: =IF(Line_productivity[[#This Row],[Product_id]]<>C4, 1, 0) -> 0 | L5: =IF(VLOOKUP(Line_productivity[[#This Row],[Product_id]], Products!$A$2:$C$7, 3, 0)="2 L", 2, 0.6) -> 0.6
A6: 422115 | B6: 45533 | C6: LE-600 | D6: Charlie | E6: 0.80208333 | F6: 0.86041667 | G6: =MOD(Line_productivity[[#This Row],[End Time]] - Line_productivity[[#This Row],[Start Time]], 1) * 1440 -> 84 | H6: 0.058333333 | I6: Afternoon | J6: Delayed | K6: =IF(Line_productivity[[#This Row],[Product_id]]<>C5, 1, 0) -> 0 | L6: =IF(VLOOKUP(Line_productivity[[#This Row],[Product_id]], Products!$A$2:$C$7, 3, 0)="2 L", 2, 0.6) -> 0.6
A7: 422116 | B7: 45533 | C7: LE-600 | D7: Charlie | E7: 0.86041667 | F7: 0.90208333 | G7: =MOD(Line_productivity[[#This Row],[End Time]] - Line_productivity[[#This Row],[Start Time]], 1) * 1440 -> 60 | H7: 0.041666667 | I7: Afternoon | J7: On Time | K7: =IF(Line_productivity[[#This Row],[Product_id]]<>C6, 1, 0) -> 0 | L7: =IF(VLOOKUP(Line_productivity[[#This Row],[Product_id]], Products!$A$2:$C$7, 3, 0)="2 L", 2, 0.6) -> 0.6
A8: 422117 | B8: 45533 | C8: LE-600 | D8: Charlie | E8: 0.90208333 | F8: 0.95416667 | G8: =MOD(Line_productivity[[#This Row],[End Time]] - Line_productivity[[#This Row],[Start Time]], 1) * 1440 -> 75 | H8: 0.052083333 | I8: Afternoon | J8: Delayed | K8: =IF(Line_productivity[[#This Row],[Product_id]]<>C7, 1, 0) -> 0 | L8: =IF(VLOOKUP(Line_productivity[[#This Row],[Product_id]], Products!$A$2:$C$7, 3, 0)="2 L", 2, 0.6) -> 0.6
A9: 422118 | B9: 45534 | C9: CO-600 | D9: Dee | E9: 0.17013889 | F9: 0.25347222 | G9: =MOD(Line_productivity[[#This Row],[End Time]] - Line_productivity[[#This Row],[Start Time]], 1) * 1440 -> 120 | H9: 0.083333333 | I9: Night | J9: Delayed | K9: =IF(Line_productivity[[#This Row],[Product_id]]<>C8, 1, 0) -> 1 | L9: =IF(VLOOKUP(Line_productivity[[#This Row],[Product_id]], Products!$A$2:$C$7, 3, 0)="2 L", 2, 0.6) -> 0.6
A10: 422119 | B10: 45534 | C10: CO-600 | D10: Dee | E10: 0.25347222 | F10: 0.3125 | G10: =MOD(Line_productivity[[#This Row],[End Time]] - Line_productivity[[#This Row],[Start Time]], 1) * 1440 -> 85 | H10: 0.059027778 | I10: Morning | J10: Delayed | K10: =IF(Line_productivity[[#This Row],[Product_id]]<>C9, 1, 0) -> 0 | L10: =IF(VLOOKUP(Line_productivity[[#This Row],[Product_id]], Products!$A$2:$C$7, 3, 0)="2 L", 2, 0.6) -> 0.6
A11: 422120 | B11: 45534 | C11: CO-600 | D11: Dee | E11: 0.3125 | F11: 0.39027778 | G11: =MOD(Line_productivity[[#This Row],[End Time]] - Line_productivity[[#This Row],[Start Time]], 1) * 1440 -> 112 | H11: 0.077777778 | I11: Morning | J11: Delayed | K11: =IF(Line_productivity[[#This Row],[Product_id]]<>C10, 1, 0) -> 0 | L11: =IF(VLOOKUP(Line_productivity[[#This Row],[Product_id]], Products!$A$2:$C$7, 3, 0)="2 L", 2, 0.6) -> 0.6
A12: 422121 | B12: 45534 | C12: CO-600 | D12: Dennis | E12: 0.39027778 | F12: 0.44236111 | G12: =MOD(Line_productivity[[#This Row],[End Time]] - Line_productivity[[#This Row],[Start Time]], 1) * 1440 -> 75 | H12: 0.052083333 | I12: Morning | J12: Delayed | K12: =IF(Line_productivity[[#This Row],[Product_id]]<>C11, 1, 0) -> 0 | L12: =IF(VLOOKUP(Line_productivity[[#This Row],[Product_id]], Products!$A$2:$C$7, 3, 0)="2 L", 2, 0.6) -> 0.6
A13: 422122 | B13: 45534 | C13: CO-600 | D13: Dennis | E13: 0.44236111 | F13: 0.50138889 | G13: =MOD(Line_productivity[[#This Row],[End Time]] - Line_productivity[[#This Row],[Start Time]], 1) * 1440 -> 85 | H13: 0.059027778 | I13: Morning | J13: Delayed | K13: =IF(Line_productivity[[#This Row],[Product_id]]<>C12, 1, 0) -> 0 | L13: =IF(VLOOKUP(Line_productivity[[#This Row],[Product_id]], Products!$A$2:$C$7, 3, 0)="2 L", 2, 0.6) -> 0.6
... A39: 422148 | B39: 45538 | C39: CO-2L | D39: Mac | E39: 0.95486111 | F39: 0.045138889 | G39: =MOD(Line_productivity[[#This Row],[End Time]] - Line_productivity[[#This Row],[Start Time]], 1) * 1440 -> 130 | H39: 0.090277778 | I39: Night | J39: Delayed | K39: =IF(Line_productivity[[#This Row],[Product_id]]<>C38, 1, 0) -> 0 | L39: =IF(VLOOKUP(Line_productivity[[#This Row],[Product_id]], Products!$A$2:$C$7, 3, 0)="2 L", 2, 0.6) -> 2

Sheet Products
A1: Product_id | B1: Flavor | C1: Size | D1: Min batch time
A2: OR-600 | B2: Orange | C2: 600 ml | D2: 60
A3: LE-600 | B3: Lemon lime | C3: 600 ml | D3: 60
A4: CO-600 | B4: Cola | C4: 600 ml | D4: 60
A5: DC-600 | B5: Diet Cola | C5: 600 ml | D5: 60
A6: RB-600 | B6: Root Berry | C6: 600 ml | D6: 60
A7: CO-2L | B7: Cola | C7: 2 L | D7: 98

Sheet Downtime_factors
A1: Factor_id | B1: Description | C1: Operator Error
A2: 1 | B2: Emergency stop | C2: Non Operator
A3: 2 | B3: Batch change | C3: Operator
A4: 3 | B4: Labeling error | C4: Non Operator
A5: 4 | B5: Inventory shortage | C5: Non Operator
A6: 5 | B6: Product spill | C6: Operator
A7: 6 | B7: Machine adjustment | C7: Operator
A8: 7 | B8: Machine failure | C8: Non Operator
A9: 8 | B9: Batch coding error | C9: Operator
A10: 9 | B10: Conveyor belt jam | C10: Non Operator
A11: 10 | B11: Calibration error | C11: Operator
A12: 11 | B12: Label switch | C12: Operator
A13: 12 | B13: Other | C13: Non Operator

Sheet Line_downtime
A1: Downtime_id | B1: Batch | C1: Factor_id | D1: Duration_MIn
A2: 1 | B2: 422111 | C2: 2 | D2: 60
A3: 2 | B3: 422111 | C3: 7 | D3: 15
A4: 3 | B4: 422112 | C4: 2 | D4: 20
A5: 4 | B5: 422112 | C5: 8 | D5: 20
A6: 5 | B6: 422113 | C6: 2 | D6: 50
A7: 6 | B7: 422114 | C7: 4 | D7: 25
A8: 7 | B8: 422114 | C8: 6 | D8: 15
A9: 8 | B9: 422115 | C9: 10 | D9: 24
A10: 9 | B10: 422117 | C10: 2 | D10: 10
A11: 10 | B11: 422117 | C11: 6 | D11: 5
A12: 11 | B12: 422118 | C12: 6 | D12: 14
A13: 12 | B13: 422118 | C13: 7 | D13: 16
... A62: 61 | B62: 422148 | C62: 8 | D62: 7
